[ 2025-08-31 13:54:40,388 ] 97 werkzeug  - INFO  - [31m[1mWARNING: This is a development server. Do not use it in a production deployment. Use a production WSGI server instead.[0m
 * Running on all addresses (0.0.0.0)
 * Running on http://127.0.0.1:5000
 * Running on http://192.168.1.225:5000
[ 2025-08-31 13:54:40,388 ] 97 werkzeug  - INFO  - [33mPress CTRL+C to quit[0m
[ 2025-08-31 13:54:41,603 ] 97 werkzeug  - INFO  - 127.0.0.1 - - [31/Aug/2025 13:54:41] "GET /predictdata HTTP/1.1" 200 -
[ 2025-08-31 13:54:46,999 ] 97 werkzeug  - INFO  - 127.0.0.1 - - [31/Aug/2025 13:54:46] "GET / HTTP/1.1" 200 -
[ 2025-08-31 13:54:49,785 ] 97 werkzeug  - INFO  - 127.0.0.1 - - [31/Aug/2025 13:54:49] "GET /predictdata HTTP/1.1" 200 -
[ 2025-08-31 13:54:57,946 ] 838 app  - ERROR  - Exception on /predictdata [POST]
Traceback (most recent call last):
  File "d:\Data_Analytics2\Portfolio\Python_Machine_learning\New folder\Ml_project1\src\utils.py", line 54, in load_object
    return pickle.load(file_obj)
           ^^^^^^
NameError: name 'pickle' is not defined. Did you forget to import 'pickle'

During handling of the above exception, another exception occurred:

Traceback (most recent call last):
  File "d:\Data_Analytics2\Portfolio\Python_Machine_learning\New folder\Ml_project1\src\pipeline\predict_pipeline.py", line 16, in predict
    model= load_object(file_path= model_path)
           ^^^^^^^^^^^^^^^^^^^^^^^^^^^^^^^^^^
  File "d:\Data_Analytics2\Portfolio\Python_Machine_learning\New folder\Ml_project1\src\utils.py", line 57, in load_object
    raise CustomException(e, sys)
src.exception.CustomException: Error occured in Python script name [d:\Data_Analytics2\Portfolio\Python_Machine_learning\New folder\Ml_project1\src\utils.py] line number [54] error message[name 'pickle' is not defined]

During handling of the above exception, another exception occurred:

Traceback (most recent call last):
  File "C:\Users\LENOVO\anaconda3\Lib\site-packages\flask\app.py", line 1473, in wsgi_app
    response = self.full_dispatch_request()
               ^^^^^^^^^^^^^^^^^^^^^^^^^^^^
  File "C:\Users\LENOVO\anaconda3\Lib\site-packages\flask\app.py", line 882, in full_dispatch_request
    rv = self.handle_user_exception(e)
         ^^^^^^^^^^^^^^^^^^^^^^^^^^^^^
  File "C:\Users\LENOVO\anaconda3\Lib\site-packages\flask\app.py", line 880, in full_dispatch_request
    rv = self.dispatch_request()
         ^^^^^^^^^^^^^^^^^^^^^^^
  File "C:\Users\LENOVO\anaconda3\Lib\site-packages\flask\app.py", line 865, in dispatch_request
    return self.ensure_sync(self.view_functions[rule.endpoint])(**view_args)  # type: ignore[no-any-return]
           ^^^^^^^^^^^^^^^^^^^^^^^^^^^^^^^^^^^^^^^^^^^^^^^^^^^^^^^^^^^^^^^^^
  File "d:\Data_Analytics2\Portfolio\Python_Machine_learning\New folder\Ml_project1\app.py", line 39, in predict_datapoint
    results=predict_pipeline.predict(pred_df)
            ^^^^^^^^^^^^^^^^^^^^^^^^^^^^^^^^^
  File "d:\Data_Analytics2\Portfolio\Python_Machine_learning\New folder\Ml_project1\src\pipeline\predict_pipeline.py", line 22, in predict
    raise CustomException(e, sys)
src.exception.CustomException: Error occured in Python script name [d:\Data_Analytics2\Portfolio\Python_Machine_learning\New folder\Ml_project1\src\pipeline\predict_pipeline.py] line number [16] error message[Error occured in Python script name [d:\Data_Analytics2\Portfolio\Python_Machine_learning\New folder\Ml_project1\src\utils.py] line number [54] error message[name 'pickle' is not defined]]
[ 2025-08-31 13:54:57,950 ] 97 werkzeug  - INFO  - 127.0.0.1 - - [31/Aug/2025 13:54:57] "[35m[1mPOST /predictdata HTTP/1.1[0m" 500 -
